<?xml version="1.0"?>
<robot name="LRMate">
	<material name="Yellow">
		<color rgba="1.0  1.0  0.0  1.0"/>
	</material>
	<material name="Black">
		<color rgba="0.0  0.0  0.0  1.0"/>
	</material>
	<material name="Gray">
		<color rgba="0.5  0.5  0.5  1.0"/>
	</material>
	<material name="gripper_white">
		<color rgba="1.0  1.0  1.0  1.0"/>
	</material>

	<link name="base">
		<inertial>
			<origin xyz="0.0  0.0  0.0" rpy="0.0  0.0  0.0"/>
			<mass value="0.0"/>
			<inertia ixx="0.0"  ixy="0.0"  ixz="0.0" iyy="0.0" iyz="0.0" izz="0.0" />
		</inertial>
		<visual name="base">
			<origin xyz="0.000   0.000   0.330" rpy="0.0  0.0  0.0"/>
			<geometry>
				<mesh filename="CAD/base.stl" scale="0.001   0.001   0.001"/>
			</geometry>
			<material name="Black"/>
		</visual>
		<collision>
			<origin xyz="0.000   0.000   0.330" rpy="0.0  0.0  0.0"/>
			<geometry>
				<mesh filename="CAD/base.stl" scale="0.001   0.001   0.001"/>
			</geometry>
		</collision>
	</link>
	<joint name="joint_1" type="revolute">
		<origin xyz="0.000   0.000   0.330" rpy="0.0000000000000000    0.0000000000000000    0.0000000000000000"/>
		<parent link="base"/>
		<child link="link_1"/>
		<axis xyz="0 0 1"/>
		<limit effort="224.1470270270270646" lower="-3.1415926535897931" upper="3.1415926535897931" velocity="0.8726646259971648"/>
	</joint>
	<link name="link_1">
		<inertial>
			<origin xyz="0.0185909590000000    0.0033700950000000   -0.0770907100000000" rpy="-1.5707963267948966    0.0000000000000000    0.0000000000000000"/>
			<mass value="2.3984700000000001"/>
			<inertia ixx="0.0233179728630000"  ixy="0.0000000000000000"  ixz="0.0000000000000000" iyy="0.0193776178710000" iyz="0.0000000000000000" izz="0.0139141526340000" />
		</inertial>
		<visual name="link_1">
			<origin xyz="0.050   0.000   0.000" rpy="-1.5707963267948966    0.0000000000000000    0.0000000000000000"/>
			<geometry>
				<mesh filename="CAD/link1.stl" scale="0.001   0.001   0.001"/>
			</geometry>
			<material name="Yellow"/>
		</visual>
		<collision>
			<origin xyz="0.050   0.000   0.000" rpy="-1.5707963267948966    0.0000000000000000    0.0000000000000000"/>
			<geometry>
				<mesh filename="CAD/link1.stl" scale="0.001   0.001   0.001"/>
			</geometry>
		</collision>
	</link>
	<joint name="joint_2" type="revolute">
		<origin xyz="0.050   0.000   0.000" rpy="-1.5707963267948966    0.0000000000000000    0.0000000000000000"/>
		<parent link="link_1"/>
		<child link="link_2"/>
		<axis xyz="0 0 1"/>
		<limit effort="236.6760000000000161" lower="-3.1415926535897931" upper="3.1415926535897931" velocity="0.8726646259971648"/>
	</joint>
	<link name="link_2">
		<inertial>
			<origin xyz="-0.0071079890000000   -0.1326139250000000    0.0247800790000000" rpy="3.1415926535897931    0.0000000000000000   -1.5707963267948966"/>
			<mass value="7.8018689999999999"/>
			<inertia ixx="0.0328971739050000"  ixy="0.0000000000000000"  ixz="0.0000000000000000" iyy="0.2070365793270000" iyz="0.0000000000000000" izz="0.1883991938960000" />
		</inertial>
		<visual name="link_2">
			<origin xyz="0.000  -0.440   0.000" rpy="3.1415926535897931    0.0000000000000000   -1.5707963267948966"/>
			<geometry>
				<mesh filename="CAD/link2.stl" scale="0.001   0.001   0.001"/>
			</geometry>
			<material name="Yellow"/>
		</visual>
		<collision>
			<origin xyz="0.000  -0.440   0.000" rpy="3.1415926535897931    0.0000000000000000   -1.5707963267948966"/>
			<geometry>
				<mesh filename="CAD/link2.stl" scale="0.001   0.001   0.001"/>
			</geometry>
		</collision>
	</link>
	<joint name="joint_3" type="revolute">
		<origin xyz="0.000  -0.440   0.000" rpy="3.1415926535897931    0.0000000000000000   -1.5707963267948966"/>
		<parent link="link_2"/>
		<child link="link_3"/>
		<axis xyz="0 0 1"/>
		<limit effort="94.9241379310344939" lower="-3.1415926535897931" upper="3.1415926535897931" velocity="0.8726646259971648"/>
	</joint>
	<link name="link_3">
		<inertial>
			<origin xyz="0.0057931330000000   -0.0059066300000000   -0.0207324280000000" rpy="-1.5707963267948966    0.0000000000000000    0.0000000000000000"/>
			<mass value="2.9847210000000000"/>
			<inertia ixx="0.0081019474240000"  ixy="0.0000000000000000"  ixz="0.0000000000000000" iyy="0.0068697082660000" iyz="0.0000000000000000" izz="0.0079818513480000" />
		</inertial>
		<visual name="link_3">
			<origin xyz="0.035   0.000   0.000" rpy="-1.5707963267948966    0.0000000000000000    0.0000000000000000"/>
			<geometry>
				<mesh filename="CAD/link3.stl" scale="0.001   0.001   0.001"/>
			</geometry>
			<material name="Yellow"/>
		</visual>
		<collision>
			<origin xyz="0.035   0.000   0.000" rpy="-1.5707963267948966    0.0000000000000000    0.0000000000000000"/>
			<geometry>
				<mesh filename="CAD/link3.stl" scale="0.001   0.001   0.001"/>
			</geometry>
		</collision>
	</link>
	<joint name="joint_4" type="revolute">
		<origin xyz="0.035   0.000   0.000" rpy="-1.5707963267948966    0.0000000000000000    0.0000000000000000"/>
		<parent link="link_3"/>
		<child link="link_4"/>
		<axis xyz="0 0 1"/>
		<limit effort="23.8998260869565229" lower="-3.1415926535897931" upper="3.1415926535897931" velocity="0.8726646259971648"/>
	</joint>
	<link name="link_4">
		<inertial>
			<origin xyz="-0.0002457140000000    0.0028224150000000   -0.2060611280000000" rpy="1.5707963267948966    0.0000000000000000    0.0000000000000000"/>
			<mass value="4.1441780000000001"/>
			<inertia ixx="0.0529101059260000"  ixy="0.0000000000000000"  ixz="0.0000000000000000" iyy="0.0057046189630000" iyz="0.0000000000000000" izz="0.0531509714450000" />
		</inertial>
		<visual name="link_4">
			<origin xyz="0.000   0.000  -0.420" rpy="1.5707963267948966    0.0000000000000000    0.0000000000000000"/>
			<geometry>
				<mesh filename="CAD/link4.stl" scale="0.001   0.001   0.001"/>
			</geometry>
			<material name="Yellow"/>
		</visual>
		<collision>
			<origin xyz="0.000   0.000  -0.420" rpy="1.5707963267948966    0.0000000000000000    0.0000000000000000"/>
			<geometry>
				<mesh filename="CAD/link4.stl" scale="0.001   0.001   0.001"/>
			</geometry>
		</collision>
	</link>
	<joint name="joint_5" type="revolute">
		<origin xyz="0.000   0.000  -0.420" rpy="1.5707963267948966    0.0000000000000000    0.0000000000000000"/>
		<parent link="link_4"/>
		<child link="link_5"/>
		<axis xyz="0 0 1"/>
		<limit effort="13.8166666666666664" lower="-3.1415926535897931" upper="3.1415926535897931" velocity="0.8726646259971648"/>
	</joint>
	<link name="link_5">
		<inertial>
			<origin xyz="0.0000480440000000   -0.0273839680000000   -0.0044381510000000" rpy="-1.5707963267948966    0.0000000000000000    0.0000000000000000"/>
			<mass value="1.7004200000000000"/>
			<inertia ixx="0.0024795564500000"  ixy="0.0000000000000000"  ixz="0.0000000000000000" iyy="0.0024375453070000" iyz="0.0000000000000000" izz="0.0012003431970000" />
		</inertial>
		<visual name="link_5">
			<origin xyz="0.000   0.000   0.000" rpy="-1.5707963267948966    0.0000000000000000    0.0000000000000000"/>
			<geometry>
				<mesh filename="CAD/link5.stl" scale="0.001   0.001   0.001"/>
			</geometry>
			<material name="Yellow"/>
		</visual>
		<collision>
			<origin xyz="0.000   0.000   0.000" rpy="-1.5707963267948966    0.0000000000000000    0.0000000000000000"/>
			<geometry>
				<mesh filename="CAD/link5.stl" scale="0.001   0.001   0.001"/>
			</geometry>
		</collision>
	</link>
	<joint name="joint_6" type="revolute">
		<origin xyz="0.000   0.000   0.000" rpy="-1.5707963267948966    0.0000000000000000    0.0000000000000000"/>
		<parent link="link_5"/>
		<child link="link_6"/>
		<axis xyz="0 0 1"/>
		<limit effort="6.8606896551724139" lower="-3.1415926535897931" upper="3.1415926535897931" velocity="0.8726646259971648"/>
	</joint>
	<link name="link_6">
		<inertial>
			<origin xyz="-0.0001200000000000    0.0000000000000000   -0.0705300000000000" rpy="3.1415926535897931    0.0000000000000000    0.0000000000000000"/>
			<mass value="0.1700000000000000"/>
			<inertia ixx="0.0000318000000000"  ixy="0.0000000000000000"  ixz="0.0000000000000000" iyy="0.0000315000000000" iyz="0.0000000000000000" izz="0.0000542000000000" />
		</inertial>
		<visual name="link_6">
			<origin xyz="0.000   0.000  -0.080" rpy="3.1415926535897931    0.0000000000000000    0.0000000000000000"/>
			<geometry>
				<mesh filename="CAD/link6.stl" scale="0.001   0.001   0.001"/>
			</geometry>
			<material name="Black"/>
		</visual>
		<collision>
			<origin xyz="0.000   0.000  -0.080" rpy="3.1415926535897931    0.0000000000000000    0.0000000000000000"/>
			<geometry>
				<mesh filename="CAD/link6.stl" scale="0.001   0.001   0.001"/>
			</geometry>
		</collision>
	</link>

	<link name="sensor">
        <inertial>
            <origin xyz="0 0 0" rpy="0 0 0"/>
            <mass value="0.5"/>
            <inertia ixx="0.0001"  ixy="0"  ixz="0" iyy="0.0001" iyz="0" izz="0.0001" />
        </inertial>

        <visual>
            <origin xyz="0 0 -0.102" rpy="0 0 0" />
            <geometry>
                <cylinder radius="0.025" length="0.07"/>
            </geometry>
            <material name="">
                <color rgba="0.86 0.85 0.81 1.0"/>
            </material>
        </visual>

        <collision>
            <origin xyz="0 0 -0.102" rpy="0 0 0"/>
            <geometry>
                <cylinder radius="0.025" length="0.07"/>
            </geometry>
        </collision>
    </link>

	<!-- gripper -->
	<link name="gripper_hand">
		<inertial>
			<origin rpy="0 0 0" xyz="0 0 0.04"/>
			<mass value=".81"/>
			<inertia ixx="0.1" ixy="0" ixz="0" iyy="0.1" iyz="0" izz="0.1"/>
		</inertial>
		<visual>
			<geometry>
				<mesh filename="CAD/gripper_1/visual/hand.stl" scale="0.001 0.001 0.001"/>
			</geometry>
			<material name="gripper_white"/>
		</visual>
		<collision>
		<geometry>
			<mesh filename="CAD/gripper_1/collision/hand.stl" scale="0.001 0.001 0.001"/>
		</geometry>
		<material name="gripper_white"/>
		</collision>
  	</link>

  	<link name="gripper_leftfinger">
		<contact>
			<friction_anchor/>
			<stiffness value="30000.0"/>
			<damping value="1000.0"/>
			<spinning_friction value="0.1"/>
			<lateral_friction value="1.0"/>
		</contact>
		<inertial>
			<origin rpy="0 0 0" xyz="0 0.01 0.02"/>
			<mass value="0.1"/>
			<inertia ixx="0.1" ixy="0" ixz="0" iyy="0.1" iyz="0" izz="0.1"/>
		</inertial>
		<visual>
			<geometry>
				<mesh filename="CAD/gripper_1/visual/finger_v2.stl" scale="0.001 0.001 0.001"/>
			</geometry>
			<material name="gripper_white"/>
		</visual>
		<collision>
			<geometry>
				<mesh filename="CAD/gripper_1/collision/finger_v2.stl" scale="0.001 0.001 0.001"/>
			</geometry>
			<material name="gripper_white"/>
		</collision>
	</link>

  	<link name="gripper_rightfinger">
    	<contact>
			<friction_anchor/>
			<stiffness value="30000.0"/>
			<damping value="1000.0"/>
			<spinning_friction value="0.1"/>
			<lateral_friction value="1.0"/>
		</contact>

  		<inertial>
			<origin rpy="0 0 0" xyz="0 -0.01 0.02"/>
			<mass value="0.1"/>
			<inertia ixx="0.1" ixy="0" ixz="0" iyy="0.1" iyz="0" izz="0.1"/>
		</inertial>
		<visual>
			<origin rpy="0 0 3.14159265359" xyz="0 0 0"/>
			<geometry>
				<mesh filename="CAD/gripper_1/visual/finger_v2.stl" scale="0.001 0.001 0.001"/>
			</geometry>
			<material name="gripper_white"/>
		</visual>
		<collision>
			<origin rpy="0 0 3.14159265359" xyz="0 0 0"/>
			<geometry>
				<mesh filename="CAD/gripper_1/collision/finger_v2.stl" scale="0.001 0.001 0.001"/>
			</geometry>
			<material name="gripper_white"/>
		</collision>
  	</link>



	<joint name="joint_6-sensor" type="fixed">
        <origin rpy="0 0 0" xyz="0 0 -0.014"/>
        <parent link="link_6"/>
        <child link="sensor"/>
    </joint>

    <joint name="sensor-gripper" type="fixed">
        <origin rpy="1.5707963267948966 0.0 1.5707963267948966" xyz="0.0 0.0 -0.137"/>
        <parent link="sensor"/>
        <child link="gripper_hand"/>
    </joint>

	<joint name="gripper_finger_joint1" type="prismatic">
		<parent link="gripper_hand"/>
		<child link="gripper_leftfinger"/>
		<origin rpy="0 1.5707963267948966 0" xyz="0.045 -0.078 0"/>
		<axis xyz="0 0 -1"/>
		<limit effort="20" lower="0.0" upper="0.04" velocity="0.2"/>
	</joint>


	<joint name="gripper_finger_joint2" type="prismatic">
		<parent link="gripper_hand"/>
		<child link="gripper_rightfinger"/>
		<origin rpy="3.14159265359 1.5707963267948966 0" xyz="-0.045 -0.078 0"/>
		<axis xyz="0 0 -1"/>
		<limit effort="20" lower="0.0" upper="0.04" velocity="0.2"/>
		<mimic joint="gripper_finger_joint1"/>
	</joint>


    
</robot>
