<?xml version="1.0"?>
<robot name="LRMate">
	<material name="Yellow">
		<color rgba="1.0  1.0  0.0  1.0"/>
	</material>
	<material name="Black">
		<color rgba="0.0  0.0  0.0  1.0"/>
	</material>
	<material name="Gray">
		<color rgba="0.5  0.5  0.5  1.0"/>
	</material>
	<link name="base">
		<inertial>
			<origin xyz="0.0  0.0  0.0" rpy="0.0  0.0  0.0"/>
			<mass value="0.0"/>
			<inertia ixx="0.0"  ixy="0.0"  ixz="0.0" iyy="0.0" iyz="0.0" izz="0.0" />
		</inertial>
		<visual name="base">
			<origin xyz="0.000   0.000   0.330" rpy="0.0  0.0  0.0"/>
			<geometry>
				<mesh filename="CAD/base.stl" scale="0.001   0.001   0.001"/>
			</geometry>
			<material name="Black"/>
		</visual>
		<collision>
			<origin xyz="0.000   0.000   0.330" rpy="0.0  0.0  0.0"/>
			<geometry>
				<mesh filename="CAD/base.stl" scale="0.001   0.001   0.001"/>
			</geometry>
		</collision>
	</link>
	<joint name="joint_1" type="revolute">
		<origin xyz="0.000   0.000   0.330" rpy="0.0000000000000000    0.0000000000000000    0.0000000000000000"/>
		<parent link="base"/>
		<child link="link_1"/>
		<axis xyz="0 0 1"/>
		<limit effort="224.1470270270270646" lower="-3.1415926535897931" upper="3.1415926535897931" velocity="0.8726646259971648"/>
	</joint>
	<link name="link_1">
		<inertial>
			<origin xyz="0.0185909590000000    0.0033700950000000   -0.0770907100000000" rpy="-1.5707963267948966    0.0000000000000000    0.0000000000000000"/>
			<mass value="2.3984700000000001"/>
			<inertia ixx="0.0233179728630000"  ixy="0.0000000000000000"  ixz="0.0000000000000000" iyy="0.0193776178710000" iyz="0.0000000000000000" izz="0.0139141526340000" />
		</inertial>
		<visual name="link_1">
			<origin xyz="0.050   0.000   0.000" rpy="-1.5707963267948966    0.0000000000000000    0.0000000000000000"/>
			<geometry>
				<mesh filename="CAD/link1.stl" scale="0.001   0.001   0.001"/>
			</geometry>
			<material name="Yellow"/>
		</visual>
		<collision>
			<origin xyz="0.050   0.000   0.000" rpy="-1.5707963267948966    0.0000000000000000    0.0000000000000000"/>
			<geometry>
				<mesh filename="CAD/link1.stl" scale="0.001   0.001   0.001"/>
			</geometry>
		</collision>
	</link>
	<joint name="joint_2" type="revolute">
		<origin xyz="0.050   0.000   0.000" rpy="-1.5707963267948966    0.0000000000000000    0.0000000000000000"/>
		<parent link="link_1"/>
		<child link="link_2"/>
		<axis xyz="0 0 1"/>
		<limit effort="236.6760000000000161" lower="-3.1415926535897931" upper="3.1415926535897931" velocity="0.8726646259971648"/>
	</joint>
	<link name="link_2">
		<inertial>
			<origin xyz="-0.0071079890000000   -0.1326139250000000    0.0247800790000000" rpy="3.1415926535897931    0.0000000000000000   -1.5707963267948966"/>
			<mass value="7.8018689999999999"/>
			<inertia ixx="0.0328971739050000"  ixy="0.0000000000000000"  ixz="0.0000000000000000" iyy="0.2070365793270000" iyz="0.0000000000000000" izz="0.1883991938960000" />
		</inertial>
		<visual name="link_2">
			<origin xyz="0.000  -0.440   0.000" rpy="3.1415926535897931    0.0000000000000000   -1.5707963267948966"/>
			<geometry>
				<mesh filename="CAD/link2.stl" scale="0.001   0.001   0.001"/>
			</geometry>
			<material name="Yellow"/>
		</visual>
		<collision>
			<origin xyz="0.000  -0.440   0.000" rpy="3.1415926535897931    0.0000000000000000   -1.5707963267948966"/>
			<geometry>
				<mesh filename="CAD/link2.stl" scale="0.001   0.001   0.001"/>
			</geometry>
		</collision>
	</link>
	<joint name="joint_3" type="revolute">
		<origin xyz="0.000  -0.440   0.000" rpy="3.1415926535897931    0.0000000000000000   -1.5707963267948966"/>
		<parent link="link_2"/>
		<child link="link_3"/>
		<axis xyz="0 0 1"/>
		<limit effort="94.9241379310344939" lower="-3.1415926535897931" upper="3.1415926535897931" velocity="0.8726646259971648"/>
	</joint>
	<link name="link_3">
		<inertial>
			<origin xyz="0.0057931330000000   -0.0059066300000000   -0.0207324280000000" rpy="-1.5707963267948966    0.0000000000000000    0.0000000000000000"/>
			<mass value="2.9847210000000000"/>
			<inertia ixx="0.0081019474240000"  ixy="0.0000000000000000"  ixz="0.0000000000000000" iyy="0.0068697082660000" iyz="0.0000000000000000" izz="0.0079818513480000" />
		</inertial>
		<visual name="link_3">
			<origin xyz="0.035   0.000   0.000" rpy="-1.5707963267948966    0.0000000000000000    0.0000000000000000"/>
			<geometry>
				<mesh filename="CAD/link3.stl" scale="0.001   0.001   0.001"/>
			</geometry>
			<material name="Yellow"/>
		</visual>
		<collision>
			<origin xyz="0.035   0.000   0.000" rpy="-1.5707963267948966    0.0000000000000000    0.0000000000000000"/>
			<geometry>
				<mesh filename="CAD/link3.stl" scale="0.001   0.001   0.001"/>
			</geometry>
		</collision>
	</link>
	<joint name="joint_4" type="revolute">
		<origin xyz="0.035   0.000   0.000" rpy="-1.5707963267948966    0.0000000000000000    0.0000000000000000"/>
		<parent link="link_3"/>
		<child link="link_4"/>
		<axis xyz="0 0 1"/>
		<limit effort="23.8998260869565229" lower="-3.1415926535897931" upper="3.1415926535897931" velocity="0.8726646259971648"/>
	</joint>
	<link name="link_4">
		<inertial>
			<origin xyz="-0.0002457140000000    0.0028224150000000   -0.2060611280000000" rpy="1.5707963267948966    0.0000000000000000    0.0000000000000000"/>
			<mass value="4.1441780000000001"/>
			<inertia ixx="0.0529101059260000"  ixy="0.0000000000000000"  ixz="0.0000000000000000" iyy="0.0057046189630000" iyz="0.0000000000000000" izz="0.0531509714450000" />
		</inertial>
		<visual name="link_4">
			<origin xyz="0.000   0.000  -0.420" rpy="1.5707963267948966    0.0000000000000000    0.0000000000000000"/>
			<geometry>
				<mesh filename="CAD/link4.stl" scale="0.001   0.001   0.001"/>
			</geometry>
			<material name="Yellow"/>
		</visual>
		<collision>
			<origin xyz="0.000   0.000  -0.420" rpy="1.5707963267948966    0.0000000000000000    0.0000000000000000"/>
			<geometry>
				<mesh filename="CAD/link4.stl" scale="0.001   0.001   0.001"/>
			</geometry>
		</collision>
	</link>
	<joint name="joint_5" type="revolute">
		<origin xyz="0.000   0.000  -0.420" rpy="1.5707963267948966    0.0000000000000000    0.0000000000000000"/>
		<parent link="link_4"/>
		<child link="link_5"/>
		<axis xyz="0 0 1"/>
		<limit effort="13.8166666666666664" lower="-3.1415926535897931" upper="3.1415926535897931" velocity="0.8726646259971648"/>
	</joint>
	<link name="link_5">
		<inertial>
			<origin xyz="0.0000480440000000   -0.0273839680000000   -0.0044381510000000" rpy="-1.5707963267948966    0.0000000000000000    0.0000000000000000"/>
			<mass value="1.7004200000000000"/>
			<inertia ixx="0.0024795564500000"  ixy="0.0000000000000000"  ixz="0.0000000000000000" iyy="0.0024375453070000" iyz="0.0000000000000000" izz="0.0012003431970000" />
		</inertial>
		<visual name="link_5">
			<origin xyz="0.000   0.000   0.000" rpy="-1.5707963267948966    0.0000000000000000    0.0000000000000000"/>
			<geometry>
				<mesh filename="CAD/link5.stl" scale="0.001   0.001   0.001"/>
			</geometry>
			<material name="Yellow"/>
		</visual>
		<collision>
			<origin xyz="0.000   0.000   0.000" rpy="-1.5707963267948966    0.0000000000000000    0.0000000000000000"/>
			<geometry>
				<mesh filename="CAD/link5.stl" scale="0.001   0.001   0.001"/>
			</geometry>
		</collision>
	</link>
	<joint name="joint_6" type="revolute">
		<origin xyz="0.000   0.000   0.000" rpy="-1.5707963267948966    0.0000000000000000    0.0000000000000000"/>
		<parent link="link_5"/>
		<child link="link_6"/>
		<axis xyz="0 0 1"/>
		<limit effort="6.8606896551724139" lower="-3.1415926535897931" upper="3.1415926535897931" velocity="0.8726646259971648"/>
	</joint>
	<link name="link_6">
		<inertial>
			<origin xyz="-0.0001200000000000    0.0000000000000000   -0.0705300000000000" rpy="3.1415926535897931    0.0000000000000000    0.0000000000000000"/>
			<mass value="0.1700000000000000"/>
			<inertia ixx="0.0000318000000000"  ixy="0.0000000000000000"  ixz="0.0000000000000000" iyy="0.0000315000000000" iyz="0.0000000000000000" izz="0.0000542000000000" />
		</inertial>
		<visual name="link_6">
			<origin xyz="0.000   0.000  -0.080" rpy="3.1415926535897931    0.0000000000000000    0.0000000000000000"/>
			<geometry>
				<mesh filename="CAD/link6.stl" scale="0.001   0.001   0.001"/>
			</geometry>
			<material name="Black"/>
		</visual>
		<collision>
			<origin xyz="0.000   0.000  -0.080" rpy="3.1415926535897931    0.0000000000000000    0.0000000000000000"/>
			<geometry>
				<mesh filename="CAD/link6.stl" scale="0.001   0.001   0.001"/>
			</geometry>
		</collision>
	</link>
    <link name="flange"/>
    <joint name="joint_6-flange" type="fixed">
        <origin rpy="0 0 0" xyz="0 0 0"/>
        <parent link="link_6"/>
        <child link="flange"/>
    </joint>

    <joint name="fanuc_m10ia/bhand/bhand_base_joint" type="fixed">
        <parent link="flange"/>
        <child link="fanuc_m10ia/bhand/bhand_palm_link"/>
        <origin rpy="0.0 3.1415926535897931 3.1415926535897931" xyz="0 0 -0.080"/>
    </joint>

    <gazebo reference="fanuc_m10ia/bhand/bhand_palm_link">
        <mu1>0.8</mu1>
        <mu2>0.8</mu2>
    </gazebo>
    <link name="fanuc_m10ia/bhand/bhand_palm_link">
        <inertial>
        <origin xyz="-5.1098e-005 0.0050433 0.036671"/>
        <mass value="0.50573"/>
        <inertia ixx="3.8374e-005" ixy="-5.604e-008" ixz="-4.2034e-005" iyy="0.00022405" iyz="1.3283e-007" izz="0.00020045"/>
        </inertial>
        <visual>
        <material name="">
            <color rgba="0.86 0.85 0.81 1.0"/>
        </material>
        <geometry>
            <mesh filename="package://barrett_model/models/sw_meshes/bhand/bhand_palm_fine.stl"/>
        </geometry>
        </visual>
        <collision>
        <geometry>
            <mesh filename="package://barrett_model/models/sw_meshes/bhand/bhand_palm_link_convex_decomposition.dae"/>
        </geometry>
        </collision>
    </link>
    <joint name="fanuc_m10ia/bhand/bhand_palm_surface_joint" type="fixed">
        <parent link="fanuc_m10ia/bhand/bhand_palm_link"/>
        <child link="fanuc_m10ia/bhand/bhand_palm_surface_link"/>
        <origin rpy="0 0 0" xyz="0 0 0.08"/>
        <limit effort="5" lower="0" upper="3.14159265359" velocity="5.0"/>
        <dynamics damping="0.11" friction="0"/>
    </joint>
    <link name="fanuc_m10ia/bhand/bhand_palm_surface_link">
        <inertial>
        <mass value="0.000001"/>
        <inertia ixx="0.000001" ixy="0.0" ixz="0.0" iyy="0.000001" iyz="0.0" izz="0.000001"/>
        </inertial>
    </link>
    <joint name="fanuc_m10ia/bhand/bhand_grasp_joint" type="fixed">
        <parent link="fanuc_m10ia/bhand/bhand_palm_link"/>
        <child link="fanuc_m10ia/bhand/bhand_grasp_link"/>
        <origin rpy="0 0 0" xyz="0 0 0.12"/>
        <limit effort="5" lower="0" upper="3.14159265359" velocity="5.0"/>
        <dynamics damping="0.11" friction="0"/>
    </joint>
    <link name="fanuc_m10ia/bhand/bhand_grasp_link">
        <inertial>
        <mass value="0.000001"/>
        <inertia ixx="0.000001" ixy="0.0" ixz="0.0" iyy="0.000001" iyz="0.0" izz="0.000001"/>
        </inertial>
    </link>
    <joint name="fanuc_m10ia/bhand/finger_1/prox_joint" type="revolute">
        <parent link="fanuc_m10ia/bhand/bhand_palm_link"/>
        <child link="fanuc_m10ia/bhand/finger_1/prox_link"/>
        <origin rpy="0 0 -1.57079632679" xyz="-0.025 0.0 0.0415"/>
        <axis xyz="0 0 -1"/>
        <limit effort="5" lower="0" upper="3.14159265359" velocity="5.0"/>
        <dynamics damping="0.11" friction="0"/>
    </joint>
    <gazebo reference="fanuc_m10ia/bhand/finger_1/prox_joint">
        <provideFeedback>true</provideFeedback>
        <implicitSpringDamper>true</implicitSpringDamper>
        <!--<kp>0.0</kp>[> CFM <]-->
        <!--<kd>0.0</kd>[> ERP <]-->
        <!--<cfmDamping>true</cfmDamping>-->
        <!--<dynamics damping="5.5" friction="1"/>-->
    </gazebo>
    <gazebo reference="fanuc_m10ia/bhand/finger_1/prox_link">
        <mu1>0.8</mu1>
        <mu2>0.8</mu2>
    </gazebo>
    <link name="fanuc_m10ia/bhand/finger_1/prox_link">
        <inertial>
        <origin xyz="0.023133 0.00078642 0.00052792"/>
        <mass value="0.14109"/>
        <inertia ixx="4.872e-006" ixy="1.7103e-006" ixz="3.4041e-008" iyy="7.6588e-005" iyz="2.3133e-008" izz="7.7733e-005"/>
        </inertial>
        <visual>
        <material name="">
            <color rgba="0.86 0.85 0.81 1.0"/>
        </material>
        <geometry>
            <mesh filename="package://barrett_model/models/sw_meshes/bhand/bhand_finger_prox_link_fine.stl"/>
        </geometry>
        </visual>
        <collision>
        <geometry>
            <mesh filename="package://barrett_model/models/sw_meshes/bhand/bhand_finger_prox_link_convex_decomposition.dae"/>
        </geometry>
        </collision>
    </link>
    <joint name="fanuc_m10ia/bhand/finger_1/med_joint" type="revolute">
        <parent link="fanuc_m10ia/bhand/finger_1/prox_link"/>
        <child link="fanuc_m10ia/bhand/finger_1/med_link"/>
        <origin rpy="1.57079632679 0 0" xyz="0.05 0.0 0.03390"/>
        <axis xyz="0 0 1"/>
        <limit effort="5" lower="0" upper="2.44346095279" velocity="5.00"/>
        <dynamics damping="0.11" friction="0"/>
    </joint>
    <gazebo reference="fanuc_m10ia/bhand/finger_1/med_joint">
        <provideFeedback>true</provideFeedback>
        <implicitSpringDamper>true</implicitSpringDamper>
        <!--<kp>0.0</kp>[> CFM <]-->
        <!--<kd>0.0</kd>[> ERP <]-->
        <!--<cfmDamping>true</cfmDamping>-->
        <!--<dynamics damping="5.5" friction="1"/>-->
    </gazebo>
    <gazebo reference="fanuc_m10ia/bhand/finger_1/med_link">
        <mu1>0.8</mu1>
        <mu2>0.8</mu2>
    </gazebo>
    <link name="fanuc_m10ia/bhand/finger_1/med_link">
        <inertial>
        <origin xyz="0.023133 0.00078642 0.00052792"/>
        <mass value="0.062139"/>
        <inertia ixx="4.872e-006" ixy="1.7103e-006" ixz="3.4041e-008" iyy="7.6588e-005" iyz="2.3133e-008" izz="7.7733e-005"/>
        </inertial>
        <visual>
        <material name="">
            <color rgba="0.86 0.85 0.81 1.0"/>
        </material>
        <geometry>
            <mesh filename="package://barrett_model/models/sw_meshes/bhand/bhand_finger_med_link_fine.stl"/>
        </geometry>
        </visual>
        <collision>
        <geometry>
            <mesh filename="package://barrett_model/models/sw_meshes/bhand/bhand_finger_med_link_convex.dae"/>
        </geometry>
        </collision>
    </link>
    <joint name="fanuc_m10ia/bhand/finger_1/dist_joint" type="revolute">
        <parent link="fanuc_m10ia/bhand/finger_1/med_link"/>
        <child link="fanuc_m10ia/bhand/finger_1/dist_link"/>
        <origin rpy="0 0 0.785398163397" xyz="0.06994 0.003 0.0"/>
        <axis xyz="0 0 1"/>
        <limit effort="5" lower="0" upper="0.837758040957" velocity="5.00"/>
        <dynamics damping="0.11" friction="0"/>
    </joint>
    <gazebo reference="fanuc_m10ia/bhand/finger_1/dist_joint">
        <provideFeedback>true</provideFeedback>
        <implicitSpringDamper>true</implicitSpringDamper>
        <!--<kp>0.0</kp>[> CFM <]-->
        <!--<kd>0.0</kd>[> ERP <]-->
        <!--<cfmDamping>true</cfmDamping>-->
        <!--<dynamics damping="5.5" friction="1"/>-->
    </gazebo>
    <gazebo reference="fanuc_m10ia/bhand/finger_1/dist_link">
        <mu1>0.8</mu1>
        <mu2>0.8</mu2>
        <selfCollide>true</selfCollide>
    </gazebo>
    <link name="fanuc_m10ia/bhand/finger_1/dist_link">
        <inertial>
        <origin rpy="0 0 0" xyz="0.022825 0.0010491 0.0004203"/>
        <mass value="0.041377"/>
        <inertia ixx="3.1582e-006" ixy="1.4308e-006" ixz="1.0106e-007" iyy="3.8376e-005" iyz="0" izz="3.7275e-005"/>
        </inertial>
        <visual>
        <origin rpy="0 0 -0.785398163397"/>
        <material name="">
            <color rgba="0.86 0.85 0.81 1.0"/>
        </material>
        <geometry>
            <mesh filename="package://barrett_model/models/sw_meshes/bhand/bhand_finger_dist_link_fine.stl"/>
        </geometry>
        </visual>
        <collision>
        <origin rpy="0 0 -0.785398163397"/>
        <geometry>
            <mesh filename="package://barrett_model/models/sw_meshes/bhand/bhand_finger_dist_link_convex.dae"/>
        </geometry>
        </collision>
    </link>
    <joint name="fanuc_m10ia/bhand/finger_1/tip_joint" type="fixed">
        <parent link="fanuc_m10ia/bhand/finger_1/dist_link"/>
        <child link="fanuc_m10ia/bhand/finger_1/tip_link"/>
        <origin rpy="0 0 0" xyz="0.05 0.0 0.0"/>
    </joint>
    <link name="fanuc_m10ia/bhand/finger_1/tip_link">
        <inertial>
        <mass value="1E-6"/>
        <inertia ixx="1E-6" ixy="0" ixz="0" iyy="1E-6" iyz="0" izz="1E-6"/>
        </inertial>
    </link>
    <joint name="fanuc_m10ia/bhand/finger_2/prox_joint" type="revolute">
        <parent link="fanuc_m10ia/bhand/bhand_palm_link"/>
        <child link="fanuc_m10ia/bhand/finger_2/prox_link"/>
        <origin rpy="0 0 -1.57079632679" xyz="0.025 0.0 0.0415"/>
        <axis xyz="0 0 1"/>
        <limit effort="5" lower="0" upper="3.14159265359" velocity="5.0"/>
        <dynamics damping="0.11" friction="0"/>
    </joint>
    <gazebo reference="fanuc_m10ia/bhand/finger_2/prox_joint">
        <provideFeedback>true</provideFeedback>
        <implicitSpringDamper>true</implicitSpringDamper>
        <!--<kp>0.0</kp>[> CFM <]-->
        <!--<kd>0.0</kd>[> ERP <]-->
        <!--<cfmDamping>true</cfmDamping>-->
        <!--<dynamics damping="5.5" friction="1"/>-->
    </gazebo>
    <gazebo reference="fanuc_m10ia/bhand/finger_2/prox_link">
        <mu1>0.8</mu1>
        <mu2>0.8</mu2>
    </gazebo>
    <link name="fanuc_m10ia/bhand/finger_2/prox_link">
        <inertial>
        <origin xyz="0.023133 0.00078642 0.00052792"/>
        <mass value="0.14109"/>
        <inertia ixx="4.872e-006" ixy="1.7103e-006" ixz="3.4041e-008" iyy="7.6588e-005" iyz="2.3133e-008" izz="7.7733e-005"/>
        </inertial>
        <visual>
        <material name="">
            <color rgba="0.86 0.85 0.81 1.0"/>
        </material>
        <geometry>
            <mesh filename="package://barrett_model/models/sw_meshes/bhand/bhand_finger_prox_link_fine.stl"/>
        </geometry>
        </visual>
        <collision>
        <geometry>
            <mesh filename="package://barrett_model/models/sw_meshes/bhand/bhand_finger_prox_link_convex_decomposition.dae"/>
        </geometry>
        </collision>
    </link>
    <joint name="fanuc_m10ia/bhand/finger_2/med_joint" type="revolute">
        <parent link="fanuc_m10ia/bhand/finger_2/prox_link"/>
        <child link="fanuc_m10ia/bhand/finger_2/med_link"/>
        <origin rpy="1.57079632679 0 0" xyz="0.05 0.0 0.03390"/>
        <axis xyz="0 0 1"/>
        <limit effort="5" lower="0" upper="2.44346095279" velocity="5.00"/>
        <dynamics damping="0.11" friction="0"/>
    </joint>
    <gazebo reference="fanuc_m10ia/bhand/finger_2/med_joint">
        <provideFeedback>true</provideFeedback>
        <implicitSpringDamper>true</implicitSpringDamper>
        <!--<kp>0.0</kp>[> CFM <]-->
        <!--<kd>0.0</kd>[> ERP <]-->
        <!--<cfmDamping>true</cfmDamping>-->
        <!--<dynamics damping="5.5" friction="1"/>-->
    </gazebo>
    <gazebo reference="fanuc_m10ia/bhand/finger_2/med_link">
        <mu1>0.8</mu1>
        <mu2>0.8</mu2>
    </gazebo>
    <link name="fanuc_m10ia/bhand/finger_2/med_link">
        <inertial>
        <origin xyz="0.023133 0.00078642 0.00052792"/>
        <mass value="0.062139"/>
        <inertia ixx="4.872e-006" ixy="1.7103e-006" ixz="3.4041e-008" iyy="7.6588e-005" iyz="2.3133e-008" izz="7.7733e-005"/>
        </inertial>
        <visual>
        <material name="">
            <color rgba="0.86 0.85 0.81 1.0"/>
        </material>
        <geometry>
            <mesh filename="package://barrett_model/models/sw_meshes/bhand/bhand_finger_med_link_fine.stl"/>
        </geometry>
        </visual>
        <collision>
        <geometry>
            <mesh filename="package://barrett_model/models/sw_meshes/bhand/bhand_finger_med_link_convex.dae"/>
        </geometry>
        </collision>
    </link>
    <joint name="fanuc_m10ia/bhand/finger_2/dist_joint" type="revolute">
        <parent link="fanuc_m10ia/bhand/finger_2/med_link"/>
        <child link="fanuc_m10ia/bhand/finger_2/dist_link"/>
        <origin rpy="0 0 0.785398163397" xyz="0.06994 0.003 0.0"/>
        <axis xyz="0 0 1"/>
        <limit effort="5" lower="0" upper="0.837758040957" velocity="5.00"/>
        <dynamics damping="0.11" friction="0"/>
    </joint>
    <gazebo reference="fanuc_m10ia/bhand/finger_2/dist_joint">
        <provideFeedback>true</provideFeedback>
        <implicitSpringDamper>true</implicitSpringDamper>
        <!--<kp>0.0</kp>[> CFM <]-->
        <!--<kd>0.0</kd>[> ERP <]-->
        <!--<cfmDamping>true</cfmDamping>-->
        <!--<dynamics damping="5.5" friction="1"/>-->
    </gazebo>
    <gazebo reference="fanuc_m10ia/bhand/finger_2/dist_link">
        <mu1>0.8</mu1>
        <mu2>0.8</mu2>
        <selfCollide>true</selfCollide>
    </gazebo>
    <link name="fanuc_m10ia/bhand/finger_2/dist_link">
        <inertial>
        <origin rpy="0 0 0" xyz="0.022825 0.0010491 0.0004203"/>
        <mass value="0.041377"/>
        <inertia ixx="3.1582e-006" ixy="1.4308e-006" ixz="1.0106e-007" iyy="3.8376e-005" iyz="0" izz="3.7275e-005"/>
        </inertial>
        <visual>
        <origin rpy="0 0 -0.785398163397"/>
        <material name="">
            <color rgba="0.86 0.85 0.81 1.0"/>
        </material>
        <geometry>
            <mesh filename="package://barrett_model/models/sw_meshes/bhand/bhand_finger_dist_link_fine.stl"/>
        </geometry>
        </visual>
        <collision>
        <origin rpy="0 0 -0.785398163397"/>
        <geometry>
            <mesh filename="package://barrett_model/models/sw_meshes/bhand/bhand_finger_dist_link_convex.dae"/>
        </geometry>
        </collision>
    </link>
    <joint name="fanuc_m10ia/bhand/finger_2/tip_joint" type="fixed">
        <parent link="fanuc_m10ia/bhand/finger_2/dist_link"/>
        <child link="fanuc_m10ia/bhand/finger_2/tip_link"/>
        <origin rpy="0 0 0" xyz="0.05 0.0 0.0"/>
    </joint>
    <link name="fanuc_m10ia/bhand/finger_2/tip_link">
        <inertial>
        <mass value="1E-6"/>
        <inertia ixx="1E-6" ixy="0" ixz="0" iyy="1E-6" iyz="0" izz="1E-6"/>
        </inertial>
    </link>
    <joint name="fanuc_m10ia/bhand/finger_3/med_joint" type="revolute">
        <parent link="fanuc_m10ia/bhand/bhand_palm_link"/>
        <child link="fanuc_m10ia/bhand/finger_3/med_link"/>
        <origin rpy="1.57079632679 0 1.57079632679" xyz="0 0.05 0.0754"/>
        <axis xyz="0 0 1"/>
        <limit effort="5" lower="0" upper="2.44346095279" velocity="5.00"/>
        <dynamics damping="0.11" friction="0"/>
    </joint>
    <gazebo reference="fanuc_m10ia/bhand/finger_3/med_joint">
        <provideFeedback>true</provideFeedback>
        <implicitSpringDamper>true</implicitSpringDamper>
        <!--<kp>0.0</kp>[> CFM <]-->
        <!--<kd>0.0</kd>[> ERP <]-->
        <!--<cfmDamping>true</cfmDamping>-->
        <!--<dynamics damping="5.5" friction="1"/>-->
    </gazebo>
    <gazebo reference="fanuc_m10ia/bhand/finger_3/med_link">
        <mu1>0.8</mu1>
        <mu2>0.8</mu2>
    </gazebo>
    <link name="fanuc_m10ia/bhand/finger_3/med_link">
        <inertial>
        <origin xyz="0.023133 0.00078642 0.00052792"/>
        <mass value="0.062139"/>
        <inertia ixx="4.872e-006" ixy="1.7103e-006" ixz="3.4041e-008" iyy="7.6588e-005" iyz="2.3133e-008" izz="7.7733e-005"/>
        </inertial>
        <visual>
        <material name="">
            <color rgba="0.86 0.85 0.81 1.0"/>
        </material>
        <geometry>
            <mesh filename="package://barrett_model/models/sw_meshes/bhand/bhand_finger_med_link_fine.stl"/>
        </geometry>
        </visual>
        <collision>
        <geometry>
            <mesh filename="package://barrett_model/models/sw_meshes/bhand/bhand_finger_med_link_convex.dae"/>
        </geometry>
        </collision>
    </link>
    <joint name="fanuc_m10ia/bhand/finger_3/dist_joint" type="revolute">
        <parent link="fanuc_m10ia/bhand/finger_3/med_link"/>
        <child link="fanuc_m10ia/bhand/finger_3/dist_link"/>
        <origin rpy="0 0 0.785398163397" xyz="0.06994 0.003 0.0"/>
        <axis xyz="0 0 1"/>
        <limit effort="5" lower="0" upper="0.837758040957" velocity="5.00"/>
        <dynamics damping="0.11" friction="0"/>
    </joint>
    <gazebo reference="fanuc_m10ia/bhand/finger_3/dist_joint">
        <provideFeedback>true</provideFeedback>
        <implicitSpringDamper>true</implicitSpringDamper>
        <!--<kp>0.0</kp>[> CFM <]-->
        <!--<kd>0.0</kd>[> ERP <]-->
        <!--<cfmDamping>true</cfmDamping>-->
        <!--<dynamics damping="5.5" friction="1"/>-->
    </gazebo>
    <gazebo reference="fanuc_m10ia/bhand/finger_3/dist_link">
        <mu1>0.8</mu1>
        <mu2>0.8</mu2>
        <selfCollide>true</selfCollide>
    </gazebo>
    <link name="fanuc_m10ia/bhand/finger_3/dist_link">
        <inertial>
        <origin rpy="0 0 0" xyz="0.022825 0.0010491 0.0004203"/>
        <mass value="0.041377"/>
        <inertia ixx="3.1582e-006" ixy="1.4308e-006" ixz="1.0106e-007" iyy="3.8376e-005" iyz="0" izz="3.7275e-005"/>
        </inertial>
        <visual>
        <origin rpy="0 0 -0.785398163397"/>
        <material name="">
            <color rgba="0.86 0.85 0.81 1.0"/>
        </material>
        <geometry>
            <mesh filename="package://barrett_model/models/sw_meshes/bhand/bhand_finger_dist_link_fine.stl"/>
        </geometry>
        </visual>
        <collision>
        <origin rpy="0 0 -0.785398163397"/>
        <geometry>
            <mesh filename="package://barrett_model/models/sw_meshes/bhand/bhand_finger_dist_link_convex.dae"/>
        </geometry>
        </collision>
    </link>
    <joint name="fanuc_m10ia/bhand/finger_3/tip_joint" type="fixed">
        <parent link="fanuc_m10ia/bhand/finger_3/dist_link"/>
        <child link="fanuc_m10ia/bhand/finger_3/tip_link"/>
        <origin rpy="0 0 0" xyz="0.05 0.0 0.0"/>
    </joint>
    <link name="fanuc_m10ia/bhand/finger_3/tip_link">
        <inertial>
        <mass value="1E-6"/>
        <inertia ixx="1E-6" ixy="0" ixz="0" iyy="1E-6" iyz="0" izz="1E-6"/>
        </inertial>
    </link>
</robot>
